[2023-05-24T18:49:47.533+0400] {taskinstance.py:1103} INFO - Dependencies all met for dep_context=non-requeueable deps ti=<TaskInstance: podcast_summary.get_episodes manual__2023-05-24T14:49:34.416560+00:00 [queued]>
[2023-05-24T18:49:47.542+0400] {taskinstance.py:1103} INFO - Dependencies all met for dep_context=requeueable deps ti=<TaskInstance: podcast_summary.get_episodes manual__2023-05-24T14:49:34.416560+00:00 [queued]>
[2023-05-24T18:49:47.543+0400] {taskinstance.py:1308} INFO - Starting attempt 1 of 1
[2023-05-24T18:49:47.558+0400] {taskinstance.py:1327} INFO - Executing <Task(_PythonDecoratedOperator): get_episodes> on 2023-05-24 14:49:34.416560+00:00
[2023-05-24T18:49:47.584+0400] {standard_task_runner.py:57} INFO - Started process 109 to run task
[2023-05-24T18:49:47.594+0400] {standard_task_runner.py:84} INFO - Running: ['airflow', 'tasks', 'run', 'podcast_summary', 'get_episodes', 'manual__2023-05-24T14:49:34.416560+00:00', '--job-id', '62', '--raw', '--subdir', 'DAGS_FOLDER/podcast_summary.py', '--cfg-path', '/tmp/tmprfy_16xy']
[2023-05-24T18:49:47.599+0400] {standard_task_runner.py:85} INFO - Job 62: Subtask get_episodes
[2023-05-24T18:49:47.670+0400] {task_command.py:410} INFO - Running <TaskInstance: podcast_summary.get_episodes manual__2023-05-24T14:49:34.416560+00:00 [running]> on host DESKTOP-V010GL9.localdomain
[2023-05-24T18:49:47.755+0400] {taskinstance.py:1545} INFO - Exporting env vars: AIRFLOW_CTX_DAG_OWNER='airflow' AIRFLOW_CTX_DAG_ID='podcast_summary' AIRFLOW_CTX_TASK_ID='get_episodes' AIRFLOW_CTX_EXECUTION_DATE='2023-05-24T14:49:34.416560+00:00' AIRFLOW_CTX_TRY_NUMBER='1' AIRFLOW_CTX_DAG_RUN_ID='manual__2023-05-24T14:49:34.416560+00:00'
[2023-05-24T18:49:47.764+0400] {taskinstance.py:1824} ERROR - Task failed with exception
Traceback (most recent call last):
  File "/home/chinnu/.local/lib/python3.10/site-packages/urllib3/connection.py", line 200, in _new_conn
    sock = connection.create_connection(
  File "/home/chinnu/.local/lib/python3.10/site-packages/urllib3/util/connection.py", line 60, in create_connection
    for res in socket.getaddrinfo(host, port, family, socket.SOCK_STREAM):
  File "/usr/lib/python3.10/socket.py", line 955, in getaddrinfo
    for res in _socket.getaddrinfo(host, port, family, type, proto, flags):
socket.gaierror: [Errno -3] Temporary failure in name resolution

The above exception was the direct cause of the following exception:

Traceback (most recent call last):
  File "/home/chinnu/.local/lib/python3.10/site-packages/urllib3/connectionpool.py", line 790, in urlopen
    response = self._make_request(
  File "/home/chinnu/.local/lib/python3.10/site-packages/urllib3/connectionpool.py", line 491, in _make_request
    raise new_e
  File "/home/chinnu/.local/lib/python3.10/site-packages/urllib3/connectionpool.py", line 467, in _make_request
    self._validate_conn(conn)
  File "/home/chinnu/.local/lib/python3.10/site-packages/urllib3/connectionpool.py", line 1092, in _validate_conn
    conn.connect()
  File "/home/chinnu/.local/lib/python3.10/site-packages/urllib3/connection.py", line 604, in connect
    self.sock = sock = self._new_conn()
  File "/home/chinnu/.local/lib/python3.10/site-packages/urllib3/connection.py", line 207, in _new_conn
    raise NameResolutionError(self.host, self, e) from e
urllib3.exceptions.NameResolutionError: <urllib3.connection.HTTPSConnection object at 0x7f8d741af0a0>: Failed to resolve 'www.marketplace.org' ([Errno -3] Temporary failure in name resolution)

The above exception was the direct cause of the following exception:

Traceback (most recent call last):
  File "/home/chinnu/.local/lib/python3.10/site-packages/requests/adapters.py", line 486, in send
    resp = conn.urlopen(
  File "/home/chinnu/.local/lib/python3.10/site-packages/urllib3/connectionpool.py", line 844, in urlopen
    retries = retries.increment(
  File "/home/chinnu/.local/lib/python3.10/site-packages/urllib3/util/retry.py", line 515, in increment
    raise MaxRetryError(_pool, url, reason) from reason  # type: ignore[arg-type]
urllib3.exceptions.MaxRetryError: HTTPSConnectionPool(host='www.marketplace.org', port=443): Max retries exceeded with url: /feed/podcast/marketplace/ (Caused by NameResolutionError("<urllib3.connection.HTTPSConnection object at 0x7f8d741af0a0>: Failed to resolve 'www.marketplace.org' ([Errno -3] Temporary failure in name resolution)"))

During handling of the above exception, another exception occurred:

Traceback (most recent call last):
  File "/home/chinnu/.local/lib/python3.10/site-packages/airflow/decorators/base.py", line 220, in execute
    return_value = super().execute(context)
  File "/home/chinnu/.local/lib/python3.10/site-packages/airflow/operators/python.py", line 181, in execute
    return_value = self.execute_callable()
  File "/home/chinnu/.local/lib/python3.10/site-packages/airflow/operators/python.py", line 198, in execute_callable
    return self.python_callable(*self.op_args, **self.op_kwargs)
  File "/home/chinnu/airflow/dags/podcast_summary.py", line 38, in get_episodes
    data = requests.get(PODCAST_URL)
  File "/home/chinnu/.local/lib/python3.10/site-packages/requests/api.py", line 73, in get
    return request("get", url, params=params, **kwargs)
  File "/home/chinnu/.local/lib/python3.10/site-packages/requests/api.py", line 59, in request
    return session.request(method=method, url=url, **kwargs)
  File "/home/chinnu/.local/lib/python3.10/site-packages/requests/sessions.py", line 589, in request
    resp = self.send(prep, **send_kwargs)
  File "/home/chinnu/.local/lib/python3.10/site-packages/requests/sessions.py", line 703, in send
    r = adapter.send(request, **kwargs)
  File "/home/chinnu/.local/lib/python3.10/site-packages/requests/adapters.py", line 519, in send
    raise ConnectionError(e, request=request)
requests.exceptions.ConnectionError: HTTPSConnectionPool(host='www.marketplace.org', port=443): Max retries exceeded with url: /feed/podcast/marketplace/ (Caused by NameResolutionError("<urllib3.connection.HTTPSConnection object at 0x7f8d741af0a0>: Failed to resolve 'www.marketplace.org' ([Errno -3] Temporary failure in name resolution)"))
[2023-05-24T18:49:47.774+0400] {taskinstance.py:1345} INFO - Marking task as FAILED. dag_id=podcast_summary, task_id=get_episodes, execution_date=20230524T144934, start_date=20230524T144947, end_date=20230524T144947
[2023-05-24T18:49:47.789+0400] {standard_task_runner.py:104} ERROR - Failed to execute job 62 for task get_episodes (HTTPSConnectionPool(host='www.marketplace.org', port=443): Max retries exceeded with url: /feed/podcast/marketplace/ (Caused by NameResolutionError("<urllib3.connection.HTTPSConnection object at 0x7f8d741af0a0>: Failed to resolve 'www.marketplace.org' ([Errno -3] Temporary failure in name resolution)")); 109)
[2023-05-24T18:49:47.805+0400] {local_task_job_runner.py:225} INFO - Task exited with return code 1
[2023-05-24T18:49:47.835+0400] {taskinstance.py:2651} INFO - 0 downstream tasks scheduled from follow-on schedule check
